Workbook

Sheet Questions
A1: LBO Target Scoping Assignment
A3: You are an Associate at a leading investment bank . You have been asked to find potential leveraged buyout targets for one of your Private Equity clients and have decided to take a look at Oshkosh Corporation (Ticker OSK).
A4: Oshkosh Corporation designs, develops and manufactures purpose built vehicles and equipment that enhance safety, maximize productivity, lower total cost of ownership and simplify fleet management.
A5: In preparation for a meeting with your senior MD you have prepared the attached financial analysis. Please complete the analysis as instucted.
A7: Q1: Income Statement: Please complete the analysis of the income statement filling in the yellow colored boxes showing among other things, percent of sales, growth rates, calculate EBITDA and margin, and Cash flow for each year.
A8: Q2: Balance Sheets: Calculate the net change in working capital for each year and the capital expenditure (fixed assets) and the Profitability, Liquidity, Effficiency and Leverage ratios.
A9: Q3: Valuation: Using the information from the Income Statement and the Balance Sheet, complete the valuation including building a simple DCF
A10: Q4: Comparable company analysis (compco): Complete the comparable company table and ratio calculations and make observations about how Oshkosh compares to its peers.
A11: Q5: Conclusions: In the highlighted space below please summarize your conclusions. I do not expect a definitive recommendation but for you to highlight why this may or may not be an interesting LBO candidate for your client to make a buyout offer for this company.
A12: Preferrably write your conclusions in bullet point summary. I do not want a long essay.
A13: You are not expected to do an LBO analysis. That will come later.
A14: You are not required to do any additional research for this exercise but are welcome to if it helps you to answer questions.
... A31: 3. The company's PE ratio tends to be lower than its peers in the same industry. It's uncertain whether this means the market undervalues the company or future downturn because investor confidence is lacking.

Sheet Income Statement
A2: Consolidated Statements of Income
A3: In millions | P3: Sales
D4: Year Ended September 31, | H4: Year Ended December 31, | P4: 2021-2020 | Q4: 2022-2021 | R4: 2023-2022 | S4: 2024-2023
D5: 2020 | E5: % Sales | F5: 2021 | G5: % Sales | H5: 2022 | I5: % Sales | J5: 2023 | K5: % Sales | L5: 2024 | M5: % Sales | O5: Growth rate | P5: =F6/D6-1 -> 0.12841267 | Q5: =H6/F6-1 -> 0.070399235 | R5: =J6/H6-1 -> 0.16613137 | S5: =L6/J6-1 -> 0.11364789
A6: Net sales | D6: 6856.8 | E6: =D6/$D$6 -> 1 | F6: 7737.3 | G6: =F6/$F$6 -> 1 | H6: 8282 | I6: =H6/$H$6 -> 1 | J6: 9657.9 | K6: =J6/$J$6 -> 1 | L6: 10755.5 | M6: =L6/$L$6 -> 1
A7: Cost of goods sold | D7: 5740.4 | E7: =D7/$D$6 -> 0.83718353 | F7: 6469.1 | G7: =F7/$F$6 -> 0.83609269 | H7: 7227.6 | I7: =H7/$H$6 -> 0.87268776 | J7: 7977 | K7: =J7/$J$6 -> 0.82595595 | L7: 8786.1 | M7: =L7/$L$6 -> 0.81689368 | O7: max | P7: =MAX(P5:S5) -> 0.16613137
A8: Gross profit | D8: =+D6-D7 -> 1116.4 | E8: =D8/$D$6 -> 0.16281647 | F8: =+F6-F7 -> 1268.2 | G8: =F8/$F$6 -> 0.16390731 | H8: =+H6-H7 -> 1054.4 | I8: =H8/$H$6 -> 0.12731224 | J8: =+J6-J7 -> 1680.9 | K8: =J8/$J$6 -> 0.17404405 | L8: =+L6-L7 -> 1969.4 | M8: =L8/$L$6 -> 0.18310632 | O8: min | P8: =MIN(P5:S5) -> 0.070399235
A9: Operating expenses: | O9: mean | P9: =AVERAGE(P5:S5) -> 0.11964779
A10: Selling, administrative and other expenses | D10: =620.6-D11 -> 527.6 | E10: =D10/$D$6 -> 0.076945514 | F10: =666.5-F11 -> 571.9 | G10: =F10/$F$6 -> 0.073914673 | H10: =662.8-H11 -> 574.5 | I10: =H10/$H$6 -> 0.069367303 | J10: =810.4-127 -> 683.4 | K10: =J10/$J$6 -> 0.070760724 | L10: =852.4-L11 -> 707 | M10: =L10/$L$6 -> 0.065733811 | O10: median | P10: =MEDIAN(P5:S5) -> 0.12103028
A11: Depreciation | D11: =104-D12 -> 93 | E11: =D11/$D$6 -> 0.013563178 | F11: =104.2-F12 -> 94.6 | G11: =F11/$F$6 -> 0.012226487 | H11: =107.6-H12-H13 -> 88.3 | I11: =H11/$H$6 -> 0.010661676 | J11: =159.9-33 -> 126.9 | K11: =J11/$J$6 -> 0.013139502 | L11: =200.1-L12 -> 145.4 | M11: =L11/$L$6 -> 0.013518665
A12: Amortization of Purchased Intangibles | D12: 11 | E12: =D12/$D$6 -> 0.0016042469 | F12: 9.6 | G12: =F12/$F$6 -> 0.0012407429 | H12: 11.6 | I12: =H12/$H$6 -> 0.0014006279 | J12: 32.8 | K12: =J12/$J$6 -> 0.0033961834 | L12: 54.7 | M12: =L12/$L$6 -> 0.0050857701
A13: Intangible Asset impairment | D13: 0 | E13: =D13/$D$6 -> 0 | F13: 0 | G13: =F13/$F$6 -> 0 | H13: 7.7 | I13: =H13/$H$6 -> 0.00092972712 | J13: 0 | K13: =J13/$J$6 -> 0 | L13: 51.6 | M13: =L13/$L$6 -> 0.0047975454 | P13: EBIT Margin
A14: Total operating expenses | D14: =SUM(D10:D13) -> 631.6 | E14: =D14/$D$6 -> 0.092112939 | F14: =SUM(F10:F13) -> 676.1 | G14: =F14/$F$6 -> 0.087381903 | H14: =SUM(H10:H13) -> 682.1 | I14: =H14/$H$6 -> 0.082359333 | J14: =SUM(J10:J13) -> 843.1 | K14: =J14/$J$6 -> 0.08729641 | L14: =SUM(L10:L13) -> 958.7 | M14: =L14/$L$6 -> 0.089135791 | P14: 2020 | Q14: 2021 | R14: 2022 | S14: 2023 | T14: 2024
O15: Rate | P15: =D31/D6 -> 0.070703535 | Q15: =F31/F6 -> 0.076525403 | R15: =H31/H6 -> 0.04495291 | S15: =J31/J6 -> 0.086747637 | T15: =L31/L6 -> 0.093970527
A16: Operating Income | D16: =+D8-D14 -> 484.8 | E16: =D16/$D$6 -> 0.070703535 | F16: =+F8-F14 -> 592.1 | G16: =F16/$F$6 -> 0.076525403 | H16: =+H8-H14 -> 372.3 | I16: =H16/$H$6 -> 0.04495291 | J16: =+J8-J14 -> 837.8 | K16: =J16/$J$6 -> 0.086747637 | L16: =+L8-L14 -> 1010.7 | M16: =L16/$L$6 -> 0.093970527
O17: max | P17: =MAX(P15:T15) -> 0.093970527
A18: Other income (expense) | O18: min | P18: =MIN(P15:T15) -> 0.04495291
A19: Interest expense, net | D19: -59.3 | E19: =D19/$D$6 -> -0.0086483491 | F19: -48.2 | G19: =F19/$F$6 -> -0.0062295633 | H19: -53.4 | I19: =H19/$H$6 -> -0.0064477179 | J19: -68.6 | K19: =J19/$J$6 -> -0.0071029934 | L19: -119.5 | M19: =L19/$L$6 -> -0.011110595 | O19: mean | P19: =AVERAGE(P15:T15) -> 0.074580002
A20: Interest Income | D20: 7.5 | E20: =D20/$D$6 -> 0.0010938047 | F20: 3.5 | G20: =F20/$F$6 -> 0.00045235418 | H20: 9.5 | I20: =H20/$H$6 -> 0.0011470659 | J20: 14.8 | K20: =J20/$J$6 -> 0.0015324242 | L20: 7.6 | M20: =L20/$L$6 -> 0.00070661522 | O20: median | P20: =MEDIAN(P15:T15) -> 0.076525403
A21: Misc. Net | D21: 2.2 | E21: =D21/$D$6 -> 0.00032084938 | F21: -2.1 | G21: =F21/$F$6 -> -0.00027141251 | H21: -52.8 | I21: =H21/$H$6 -> -0.0063752717 | J21: 13.8 | K21: =J21/$J$6 -> 0.0014288821 | L21: 4.2 | M21: =L21/$L$6 -> 0.00039049788
A22: Total non-operating expenses (income) | D22: =+D19+D20+D21 -> -49.6 | E22: =D22/$D$6 -> -0.007233695 | F22: =+F19+F20+F21 -> -46.8 | G22: =F22/$F$6 -> -0.0060486216 | H22: =+H19+H20+H21 -> -96.7 | I22: =H22/$H$6 -> -0.011675924 | J22: =+J19+J20+J21 -> -40 | K22: =J22/$J$6 -> -0.0041416871 | L22: =+L19+L20+L21 -> -107.7 | M22: =L22/$L$6 -> -0.010013481 | P22: Capex
P23: 2020 | Q23: 2021 | R23: 2022 | S23: 2023 | T23: 2024
A24: Income before income taxes | D24: =+D16+D22 -> 435.2 | E24: =D24/$D$6 -> 0.06346984 | F24: =+F16+F22 -> 545.3 | G24: =F24/$F$6 -> 0.070476781 | H24: =+H16+H22 -> 275.6 | I24: =H24/$H$6 -> 0.033276986 | J24: =+J16+J22 -> 797.8 | K24: =J24/$J$6 -> 0.08260595 | L24: =+L16+L22 -> 903 | M24: =L24/$L$6 -> 0.083957045 | O24: Rate | R24: ='Balance Sheet'!C81/'Income Statement'!H6 -> 0.03913306 | S24: ='Balance Sheet'!D81/J6 -> 0.037088808 | T24: ='Balance Sheet'!E81/'Income Statement'!L6 -> 0.021570359
A25: Provision for Income Tax | D25: 111.9 | E25: =D25/$D$6 -> 0.016319566 | F25: 36.4 | G25: =F25/$F$6 -> 0.0047044835 | H25: 97.5 | I25: =H25/$H$6 -> 0.011772519 | J25: 190 | K25: =J25/$J$6 -> 0.019673014 | L25: 210 | M25: =L25/$L$6 -> 0.019524894
A26: Net income | D26: =+D24-D25 -> 323.3 | E26: =D26/$D$6 -> 0.047150274 | F26: =+F24-F25 -> 508.9 | G26: =F26/$F$6 -> 0.065772298 | H26: =+H24-H25 -> 178.1 | I26: =H26/$H$6 -> 0.021504468 | J26: =+J24-J25 -> 607.8 | K26: =J26/$J$6 -> 0.062932936 | L26: =+L24-L25 -> 693 | M26: =L26/$L$6 -> 0.064432151
O27: max | P27: =MAX(R24:T24) -> 0.03913306
A28: Tax Rate | D28: =D25/D24 -> 0.25712316 | F28: =F25/F24 -> 0.066752246 | H28: =H25/H24 -> 0.35377358 | J28: =J25/J24 -> 0.23815493 | L28: =L25/L24 -> 0.23255814 | O28: min | P28: =MIN(R24:T24) -> 0.021570359
O29: mean | P29: =AVERAGE(R24:T24) -> 0.032597409
A30: EBITDA | D30: 2020 | F30: 2021 | H30: 2022 | J30: 2023 | L30: 2024 | O30: median | P30: =MEDIAN(R24:T24) -> 0.037088808
A31: Operating income | D31: =D8-D14 -> 484.8 | F31: =F8-F14 -> 592.1 | H31: =H8-H14 -> 372.3 | J31: =J8-J14 -> 837.8 | L31: =L8-L14 -> 1010.7
A32: Depreciation | D32: =D11 -> 93 | F32: =F11 -> 94.6 | H32: =H11 -> 88.3 | J32: =J11 -> 126.9 | L32: =L11 -> 145.4
A33: Amortization of Intangibles | D33: =D12 -> 11 | F33: =F12 -> 9.6 | H33: =H12 -> 11.6 | J33: =J12 -> 32.8 | L33: =L12 -> 54.7
A34: Intangible Asset Impairmant | D34: =D13 -> 0 | F34: =F13 -> 0 | H34: =H13 -> 7.7 | J34: =J13 -> 0 | L34: =L13 -> 51.6
A35: Total EBITDA | D35: =SUM(D31:D34) -> 588.8 | F35: =SUM(F31:F34) -> 696.3 | H35: =SUM(H31:H34) -> 479.9 | J35: =SUM(J31:J34) -> 997.5 | L35: =SUM(L31:L34) -> 1262.4
A36: EBITDA Margin | D36: =D35/D6 -> 0.08587096 | F36: =F35/F6 -> 0.089992633 | H36: =H35/H6 -> 0.057944941 | J36: =J35/J6 -> 0.10328332 | L36: =L35/L6 -> 0.11737251
A38: Growth Rates
A39: Net Sales | F39: =F6/D6-1 -> 0.12841267 | H39: =H6/F6-1 -> 0.070399235 | J39: =J6/H6-1 -> 0.16613137 | L39: =L6/J6-1 -> 0.11364789
A40: Gross Profit | F40: =F8/D8-1 -> 0.13597277 | H40: =H8/F8-1 -> -0.1685854 | J40: =J8/H8-1 -> 0.59417678 | L40: =L8/J8-1 -> 0.17163424
A41: Operating Income | F41: =F16/D16-1 -> 0.22132838 | H41: =H16/F16-1 -> -0.37122108 | J41: =J16/H16-1 -> 1.2503358 | L41: =L16/J16-1 -> 0.20637384
A42: Net Income | F42: =F26/D26-1 -> 0.5740798 | H42: =H26/F26-1 -> -0.65002948 | J42: =J26/H26-1 -> 2.4126895 | L42: =L26/J26-1 -> 0.14017769
...

Sheet Balance Sheet
A2: Consolidated Balance Sheets
A3: In millions
C4: As of December 31,
B5: 2021 | C5: 2022 | D5: 2023 | E5: 2024
A6: Assets
A7: Current assets:
A8: Cash and cash equivalents | B8: 995.7 | C8: 805.9 | D8: 125.4 | E8: 204.9
A9: Trade accounts receivable, net | B9: 973.4 | C9: 1162 | D9: 1316.4 | E9: 1254.7
A10: Unbilled Receivables | B10: 440.8 | C10: 586.3 | D10: 771.6 | E10: 697.3
A11: Inventories | B11: 1550.4 | C11: 1865.6 | D11: 2131.6 | E11: 2265.7
A12: Income Taxes Receivable | B12: 250.3 | C12: 21.6 | D12: 42.2 | E12: 51.2
A13: Other Current Assets | B13: 71.7 | C13: 90.7 | D13: 93.6 | E13: 114.5
A14: Total current assets | B14: =SUM(B8:B13) -> 4282.3 | C14: =SUM(C8:C13) -> 4532.1 | D14: =SUM(D8:D13) -> 4480.8 | E14: =SUM(E8:E13) -> 4588.3
A16: Property, plant and equipment (gross) | B16: 1480.3 | C16: 1804.4 | D16: 2162.6 | E16: 2394.6
A17: Less Accumulated Depreciation | B17: -887.1 | C17: -978.2 | D17: -1093.1 | E17: -1178.1
A18: Property Plant and Equipment Net | B18: =+B16+B17 -> 593.2 | C18: =+C16+C17 -> 826.2 | D18: =+D16+D17 -> 1069.5 | E18: =+E16+E17 -> 1216.5
A19: Goodwill | B19: 1049 | C19: 1042 | D19: 1416.4 | E19: 1410
A20: Purchased Intangibles | B20: 464 | C20: 457 | D20: 830.2 | E20: 777.6
A21: Deferrred income Taxes | B21: 71.7 | C21: 134.8 | D21: 262 | E21: 259
A22: Deferred Contract Costs | B22: 0 | C22: 415.8 | D22: 710.7 | E22: 842.6
A23: Other Long Term Assets | B23: 389.5 | C23: 321.1 | D23: 359.6 | E23: 389.8
A24: Total assets | B24: =SUM(B18:B23)+B14 -> 6849.7 | C24: =SUM(C18:C23)+C14 -> 7729 | D24: =SUM(D18:D23)+D14 -> 9129.2 | E24: =SUM(E18:E23)+E14 -> 9483.8
A26: Liabilities and equity
A27: Current liabilities:
A28: Trade accounts payable | B28: 747.4 | C28: 1129 | D28: 1214.5 | E28: 1143.4
A29: Revolving Credit Facilities | B29: 0 | C29: 9.7 | D29: 175 | E29: 362.3
A30: Customer Advances | B30: 690.9 | C30: 696.7 | D30: 706.9 | E30: 648.8
A31: Payroll Related Obligations | B31: 118.4 | C31: 119.5 | D31: 242.5 | E31: 246.2
A32: Income taxes payable | B32: 221.4 | C32: 100.3 | D32: 308 | E32: 140.1
A33: Other Current Liabilities | B33: 364.2 | C33: 373.4 | D33: 442.7 | E33: 507.3
A34: Total current liabilities | B34: =SUM(B28:B33) -> 2142.3 | C34: =SUM(C28:C33) -> 2428.6 | D34: =SUM(D28:D33) -> 3089.6 | E34: =SUM(E28:E33) -> 3048.1
A36: Long-term debt | B36: 819 | C36: 595 | D36: 597.5 | E36: 599.5
A37: Long Term Customer Advances | B37: 207 | C37: 1020.5 | D37: 1190.7 | E37: 1154.4
A38: Deferred tax liabilities | B38: 0 | C38: 0 | D38: 26.8 | E38: 26.9
A39: Other long-term liabilities | B39: 476.4 | C39: 499.2 | D39: 519.3 | E39: 502.9
A40: Total Liabilities | B40: =SUM(B36:B39)+B34 -> 3644.7 | C40: =SUM(C36:C39)+C34 -> 4543.3 | D40: =SUM(D36:D39)+D34 -> 5423.9 | E40: =SUM(E36:E39)+E34 -> 5331.8
A42: Equity:
A43: Preferred Stock | B43: 0 | C43: 0 | D43: 0 | E43: 0
A44: Common stock, par value $ 0.01 per share, 75.1mm, 75.1mm, 75.1 | B44: 0.7 | C44: 0.7 | D44: 0.7 | E44: 0.7
A45: Additional paid-in capital | B45: 792.4 | C45: 806 | D45: 823 | E45: 841
...

Sheet Valuation-draft
A1: Market Capitalization of Oshkosh
F2: Equity Market | H2: LT & ST | I2: Cash | L2: Enterprise | M2: EV/EBITDA | N2: Book | O2: Market Value | P2: Market to
F3: Capitalization | H3: Debt | I3: & Equiv | J3: Net Debt | L3: Value | M3: Multiple | N3: Value | O3: Added | P3: Book
B4: Share Price | D4: Shares Outstanding | F4: in Millions | H4: in Millions | I4: in Millions | J4: in Millions | L4: in Millions | M4: x | N4: in Millions | O4: in Millions | P4: x
A5: Current | B5: 110.54 | C5: 45831 | D5: 65863963 | F5: =B5*D5/1000000 -> 7280.6025 | H5: ='Balance Sheet'!E29+'Balance Sheet'!E36 -> 961.8 | I5: ='Balance Sheet'!E8 -> 204.9 | J5: =H5-I5 -> 756.9 | L5: =J5+F5 -> 8037.5025 | N5: =+N6 -> 0 | O5: =+F5-N5 -> 7280.6025
A6: 45657 | B6: 94.62 | D6: 65863963 | L6: =J6+F6 -> 0
A7: 45289 | B7: 106.11 | D7: =75101465-9627658 -> 65473807 | L7: =J7+F7 -> 0
A8: 44925 | B8: 84.73 | D8: =75101465-9629317 -> 65472148 | L8: =J8+F8 -> 0
A13: Unlevered DCF Value
A15: Assumptions
A16: Discount Rate | C16: =K40 -> 0.074661256
A17: Perpetual Growth Rate | C17: =K38 -> 0.017841665 | K17: Terminal
F18: 1 | G18: =1+F18 -> 2 | H18: =1+G18 -> 3 | I18: =1+H18 -> 4 | J18: =1+I18 -> 5 | K18: Value
D19: Growth Rate | E19: 2024 | F19: 2025 | G19: 2026 | H19: 2027 | I19: 2028 | J19: 2029
A20: EBIT | D20: =K39 -> 0.039803631 | E20: ='Income Statement'!L31 -> 1010.7 | F20: =E20*(1+$D$20) -> 1050.9295 | G20: =F20*(1+$D$20) -> 1092.7603 | H20: =G20*(1+$D$20) -> 1136.2562 | I20: =H20*(1+$D$20) -> 1181.4833 | J20: =I20*(1+$D$20) -> 1228.5106
A21: Taxes @ | B21: =+'Income Statement'!L28 -> 0.23255814 | F21: =F20*$B$21 -> 244.40222 | G21: =G20*$B$21 -> 254.13031 | H21: =H20*$B$21 -> 264.24562 | I21: =I20*$B$21 -> 274.76356 | J21: =J20*$B$21 -> 285.70014
A23: EBIT After Tax | F23: =F20-F21 -> 806.52731 | G23: =G20-G21 -> 838.63003 | H23: =H20-H21 -> 872.01055 | I23: =I20-I21 -> 906.71973 | J23: =J20-J21 -> 942.81047
A24: (Increase)/Decrease in Working Capital | D24: 0.05 | E24: ='Balance Sheet'!E76 -> 79.9 | F24: =E24*(1+$D$24) -> 83.895 | G24: =F24*(1+$D$24) -> 88.08975 | H24: =G24*(1+$D$24) -> 92.494237 | I24: =H24*(1+$D$24) -> 97.118949 | J24: =I24*(1+$D$24) -> 101.9749
A25: Depreciation & Amortization | D25: 0.04 | E25: ='Income Statement'!L32+'Income Statement'!L33 -> 200.1 | F25: =E25*(1+$D$25) -> 208.104 | G25: =F25*(1+$D$25) -> 216.42816 | H25: =G25*(1+$D$25) -> 225.08529 | I25: =H25*(1+$D$25) -> 234.0887 | J25: =I25*(1+$D$25) -> 243.45225
A26: Cap Ex | D26: 0.04 | E26: ='Balance Sheet'!E81 -> 232 | F26: =E26*(1+$D$26) -> 241.28 | G26: =F26*(1+$D$26) -> 250.9312 | H26: =G26*(1+$D$26) -> 260.96845 | I26: =H26*(1+$D$26) -> 271.40719 | J26: =I26*(1+$D$26) -> 282.26347
A28: Unlevered After Tax Free Cash Flow | F28: =F23-F24+F25-F26 -> 689.45631 | G28: =G23-G24+G25-G26 -> 716.03724 | H28: =H23-H24+H25-H26 -> 743.63315 | I28: =I23-I24+I25-I26 -> 772.2823 | J28: =J23-J24+J25-J26 -> 802.02435 | K28: =J28*(1+C17)/(C16-C17) -> 14367.119
A29: Implied Terminal value as Multiple of Terminal EBITDA | L29: x
A31: Present Value of Free Cash Flow | F31: =F28/(1+$C$16)^F18 -> 641.55687 | G31: =G28/(1+$C$16)^G18 -> 620.00105 | H31: =H28/(1+$C$16)^H18 -> 599.16159 | I31: =I28/(1+$C$16)^I18 -> 579.01486 | J31: =J28/(1+$C$16)^J18 -> 559.53801
A32: Present Value of Terminal Value | J32: =K28/(1+C16)^J18 -> 10023.323 | K32: =J32/D35 -> 0.76968704
A35: DCF Enterprise Value | D35: =SUM(F31:J31)+J32 -> 13022.595
A36: Less Net Debt (LT &ST) | D36: =J5 -> 756.9
A37: Equity value | D37: =D35-D36 -> 12265.695 | I37: Base | J37: SD | K37: Iteration | M37: Iteration | N37: =D35 -> 13022.595
A38: DCF Value Per Share | D38: =D37/(D5/1000000) -> 186.22771 | G38: Long Term growth | I38: 0.025 | J38: 0.01 | K38: =_xlfn.NORM.INV(RAND(),I38,J38) -> 0.017841665 | M38: 1 | N38: 13789.156
A39: DCF Value /Market Price | G39: EBIT | I39: 0.05 | J39: 0.01 | K39: =_xlfn.NORM.INV(RAND(),I39,J39) -> 0.039803631 | M39: 2 | N39: 13995.183
G40: Discount rate | I40: 0.08 | J40: 0.01 | K40: =_xlfn.NORM.INV(RAND(),I40,J40) -> 0.074661256 | M40: 3 | N40: 11367.134
A41: Avg DCF value | D41: =AVERAGE(N37:N1037) -> 15042.675 | M41: 4 | N41: 13521.12
M42: 5 | N42: 14971.543
M43: 6 | N43: 13729.12
M44: 7 | N44: 10911.766
M45: 8 | N45: 11988.901
M46: 9 | N46: 20605.695
M47: 10 | N47: 23325.24
M48: 11 | N48: 15938.345
M49: 12 | N49: 9823.6597
M50: 13 | N50: 28581.151
...

Sheet Compco
A1: Comparable Company Analysis
E3: The
E4: Toro | F4: AGCO | G4: Federal | H4: Trinity | I4: Terex
A5: Name | D5: OshKosh | E5: Company | F5: Corporation | G5: Signal | H5: Industries | I5: Corporation
A6: Ticker | D6: OSK | E6: TTC | F6: AGCO | G6: FSS | H6: TRN | I6: TEX
A8: Stock Price | B8: =+'Valuation-draft'!C5 -> 45831 | D8: =+'Valuation-draft'!B5 -> 110.54 | E8: 69.04 | F8: 101.52 | G8: 100.98 | H8: 25.77 | I8: 45.09
A10: Shares Outstanding (mm) | D10: =+'Valuation-draft'!D5/1000000 -> 65.863963 | E10: 103.025 | F10: 74.675 | G10: 61.725 | H10: 83.7 | I10: 67.775
A12: Market Capitalization | D12: =D10*D8 -> 7280.6025 | E12: =E10*E8 -> 7112.846 | F12: =F10*F8 -> 7581.006 | G12: =G10*G8 -> 6232.9905 | H12: =H10*H8 -> 2156.949 | I12: =I10*I8 -> 3055.9748
A13: Debt | D13: =+'Valuation-draft'!H5 -> 961.8 | E13: 1041 | F13: 2776 | G13: 252 | H13: 5690 | I13: 2584
A14: Cash | D14: =+'Valuation-draft'!I5 -> 204.9 | E14: =1041-722 -> 319 | F14: =2776-2036 -> 740 | G14: =252-119.8 -> 132.2 | H14: =5690-5648 -> 42 | I14: =2584-2196 -> 388
A15: Net Debt | D15: =D13-D14 -> 756.9 | E15: =E13-E14 -> 722 | F15: =F13-F14 -> 2036 | G15: =G13-G14 -> 119.8 | H15: =H13-H14 -> 5648 | I15: =I13-I14 -> 2196
A17: Enterprise Value | D17: =D12+D15 -> 8037.5025 | E17: =E12+E15 -> 7834.846 | F17: =F12+F15 -> 9617.006 | G17: =G12+G15 -> 6352.7905 | H17: =H12+H15 -> 7804.949 | I17: =I12+I15 -> 5251.9748
A19: 2026 Sales F | D19: 10920 | E19: 4650 | F19: 10190 | G19: 2200 | H19: 2580 | I19: 5550
A20: 2025 Sales F | D20: 10320 | E20: 4530 | F20: 9600 | G20: 2050 | H20: 2390 | I20: 5310
A21: TTM ( 2024) Sales | D21: =+'Income Statement'!L6 -> 10755.5 | E21: 4576 | F21: 10783 | G21: 1861 | H21: 3079 | I21: 5127
A22: 2023 Sales | D22: =+'Income Statement'!J6 -> 9657.9 | E22: 4553 | F22: 14412 | G22: 1722.7 | H22: 2983 | I22: 5152
A23: 2022 Sales | D23: =+'Income Statement'!H6 -> 8282 | E23: 4514 | F23: 12651 | G23: 1434.8 | H23: 1977 | I23: 4418
A25: TTM EBITDA | D25: =+'Income Statement'!L35 -> 1262.4 | E25: 689 | F25: 58 | G25: 358 | H25: 730 | I25: 520
A27: EPS 2024 | D27: =2.89+3.34+2.93+2.58 -> 11.74 | E27: 4.04 | F27: -5.69 | G27: 3.5 | H27: 1.69 | I27: 5
A28: EPS 2025 F | D28: 10.32 | E28: 4.24 | F28: 4.17 | G28: 3.83 | H28: 1.42 | I28: 4.68
A29: EPS 2026 F | D29: 12.21 | E29: 4.64 | F29: 6.21 | G29: 4.31 | H29: 1.7 | I29: 5.58
A31: TTM EBITDA Margin | D31: =D25/D21 -> 0.11737251 | E31: =E25/E21 -> 0.15056818 | F31: =F25/F21 -> 0.0053788371 | G31: =G25/G21 -> 0.19236969 | H31: =H25/H21 -> 0.23708996 | I31: =I25/I21 -> 0.10142383
A33: Valuation
A34: Market value to TTM Sales | D34: =D12/D21 -> 0.67691902 | E34: =E12/E21 -> 1.5543807 | F34: =F12/F21 -> 0.70305166 | G34: =G12/G21 -> 3.3492695 | H34: =H12/H21 -> 0.70053556 | I34: =I12/I21 -> 0.59605515
A35: Enterprise Value to TTM Sales | D35: =D17/D21 -> 0.74729231 | E35: =E17/E21 -> 1.7121604 | F35: =F17/F21 -> 0.89186738 | G35: =G17/G21 -> 3.4136435 | H35: =H17/H21 -> 2.5348974 | I35: =I17/I21 -> 1.0243758
A36: Enterprise Value / EBITDA X | D36: =D17/D25 -> 6.3668429 | E36: =E17/E25 -> 11.371329 | F36: =F17/F25 -> 165.81045 | G36: =G17/G25 -> 17.745225 | H36: =H17/H25 -> 10.691711 | I36: =I17/I25 -> 10.099951
A37: P/E 2024 X | D37: =D8/D27 -> 9.4156729 | E37: =E8/E27 -> 17.089109 | F37: =F8/F27 -> -17.841828 | G37: =G8/G27 -> 28.851429 | H37: =H8/H27 -> 15.248521 | I37: =I8/I27 -> 9.018
A38: P/E 2025 X | D38: =D8/D28 -> 10.71124 | E38: =E8/E28 -> 16.283019 | F38: =F8/F28 -> 24.345324 | G38: =G8/G28 -> 26.365535 | H38: =H8/H28 -> 18.147887 | I38: =I8/I28 -> 9.6346154
A39: P/E 2026 X | D39: =D8/D29 -> 9.0532351 | E39: =E8/E29 -> 14.87931 | F39: =F8/F29 -> 16.347826 | G39: =G8/G29 -> 23.429234 | H39: =H8/H29 -> 15.158824 | I39: =I8/I29 -> 8.0806452
A41: Leverage
A42: Debt/ EBITDA X | D42: =D13/D25 -> 0.76188213 | E42: =E13/E25 -> 1.5108853 | F42: =F13/F25 -> 47.862069 | G42: =G13/G25 -> 0.70391061 | H42: =H13/H25 -> 7.7945205 | I42: =I13/I25 -> 4.9692308
A43: Debt/ Market Capitalization | D43: =D13/D12 -> 0.13210445 | E43: =E13/E12 -> 0.14635492 | F43: =F13/F12 -> 0.36617831 | G43: =G13/G12 -> 0.040430031 | H43: =H13/H12 -> 2.6379854 | I43: =I13/I12 -> 0.84555672
A46: Growth Rates Per Annum
A47: EPS Projected Growth | D47: =((D29/D27)^0.5)-1 -> 0.019820608 | E47: =((E29/E27)^0.5)-1 -> 0.071687852 | F47: =((F29/F27)^0.5)-1 -> #NUM! | G47: =((G29/G27)^0.5)-1 -> 0.10969751 | H47: =((H29/H27)^0.5)-1 -> 0.0029542162 | I47: =((I29/I27)^0.5)-1 -> 0.056409012
A48: Sales Growth 2022-2024 | D48: =((D21/D23)^0.5)-1 -> 0.13958753 | E48: =((E21/E23)^0.5)-1 -> 0.0068441024 | F48: =((F21/F23)^0.5)-1 -> -0.076775386 | G48: =((G21/G23)^0.5)-1 -> 0.13887878 | H48: =((H21/H23)^0.5)-1 -> 0.24796243 | I48: =((I21/I23)^0.5)-1 -> 0.077255706
A49: Sales Growth 2024- 2026 | D49: =((D19/D21)^0.5)-1 -> 0.0076182315 | E49: =((E19/E21)^0.5)-1 -> 0.008053237 | F49: =((F19/F21)^0.5)-1 -> -0.027885795 | G49: =((G19/G21)^0.5)-1 -> 0.087271874 | H49: =((H19/H21)^0.5)-1 -> -0.084612435 | I49: =((I19/I21)^0.5)-1 -> 0.040434711
A50: Sales Growth 2022-2026 | D50: =((D19/D23)^(1/4)-1) -> 0.071573224 | E50: =((E19/E23)^(1/4)-1) -> 0.0074484883 | F50: =((F19/F23)^(1/4)-1) -> -0.052645915 | G50: =((G19/G23)^(1/4)-1) -> 0.1127762 | H50: =((H19/H23)^(1/4)-1) -> 0.068816769 | I50: =((I19/I23)^(1/4)-1) -> 0.058685142
A52: How does Oshkosh compare to the comparable companies
A53: Profitability: | C53: Strong, but not top-tier
A54: Leverage: | C54: Low and LBO-friendly
...
